# 2020년 07월 05일(일요일)




## Error Handling

* throws가 있으면 무조건 try를 붙혀줘야 함

##### Swift에서 정의하는 심각도에 따른 4가지 유형의 오류

1. simple domain error (단순 도메인 오류)
	- 아래 사진에서 예에 해당사항은 저러한 것들은 하면 안된다고 정의가 되어 있는 것들은 컴파일이나 런타임에서 대부분 걸러짐
2. recoverable (복구 가능한 오류)
	- 가능하면 유저한테 알려주거나 코드를 수정하는 게 일반적임
3. universal error (범용 오류)
	- 프로그래머가 실수해서 오류가 나는 경우
4. logic failure (논리적 오류)

<img src="https://github.com/danbin920404/TIL/blob/master/SwiftGrammar/images/ErrorHandling/ErrorHandling_1.png" width="60%" height="400px">

-----

##### error를 다루기 위한 4가지 방법

* Proragating Errors Using Throwing Functions
	- Throwing Function을 이용해서 error를 전파
* Handilng Errors Using Do-Catch
	- Do-Catch문을 이용해서 오류를 컨트롤
* Converting Errors to Optional Values
	- error를 옵셔널로 변경
* Disabling Error Propagation
	-	error 전파를 비활성화

-----

##### Propagating Errors

```
1. 오류에 대한 처리를 코드의 다른 부분에서 처리하도록 throws 키워드를 명시적으로 선언
2. throws 키워드가 없을 때는 오류를 해당 함수 내에서 처리해야 함
```

* 원래 error가 발생을 하면 error가 발생한 곳에서 처리를 할 수 있겠지만 그 함수에서 작성한 내용이 error가 나더라도 함수에서 처리를 안하고 함수를 호출한 곳에서 처리를 하는 게 throws

```swift
// 아래 함수에서 error가 났을 때 처리하겠다는 로직이 없다
// 이럴 때 throws를 써주고 try만 적어주면 된다
// try: 시도를 해보고 잘 안되면 throws를 통해서 밖에서 처리
func throwError() throws {
	try "Swift".write(
		toFile: filePath,
		atomically: true,
		encoding: .utf8
	)
}
```

##### Handling Errors Using Do-Catch

* swif는 try가 do안쪽에 들어간다

```swift
do {
	// 오류가 발생할 수 있다는 것을 적고
	try expression
		// 오류가 나지 않으면 statements로직 실행
		statements
	// try부분에서 오류가 발생하면 패턴에서 어떠한 오류인지 확인하고 statements로직 실행
} catch pattern 1 {
	statements
} catch pattern 2 where condition {
	statements
	// 패턴1, 2 모두 없다면 아래 구문이 실행
} catch {
	statements
}
```

```swift
// 우선 do를 실행하고
// contentsOfFile는 어떤 파일을 받는데 path가 없을 수도 있다
// 없을 경우에는 catch문이 실행
do {
	let contents = try String(contentsOfFile: path)
	print(contents)
} catch {
	print(error)
}
```

##### Converting Errors to Optional Values

* try? 는 as? 와 같은 개념 있으면 같이 들어가고 없으면 nil 반환

```
1. try? 를 사용하여 do ~ catch 구문 없이 오류 처리 가능
2. 정상 수행 시 Optional 값 반환, 오류 발생 시 nil 반환
```

```swift
func someThrowingFunction() throws -> Int {
	code..
}

let x = try? someThrowingFunction()
```

* 위와 동일하게 do ~ catch문을 사용하면 아래와 같이 된다

```swift
let y: Int?

do {
	y = try someThrowingFunction()
} catch {
	y = nil
}
```

##### Disabling Error Propagation

* as! 랑 마찬가지로 확실할 때만 사용

```
1. do ~ catch 구문 없이 throws 메서드 처리 가능하지만 오류 발생 시 앱 Crash
2. 오류가 발생하지 않는다고 확신할 수 있는 경우에만 try! 사용
e.g. 앱 번들에 함께 제공되는 이미지 로드 등
```

```swift
let photo = try! loadImage(atPath: "./Resourves/John Appleseed.jpg")
```

-----

* enum을 사용해서 error를 넘겨주는 예

```swift
enum IntParsingError: Error {
	case overflow
	case invalidInput(String)
}

// throws를 적어 외부에서 error를 처리할 수 있게 넘겨준다
func parsingInteger(numString: String) throws -> Int {
	guard let num = Int(numString) else {
		tyrow IntParsingError.invalidInput(numString)
	}
	guard num <= Int64.max, num >= Int64.min else {
	throw IntParsingError.overflow
	}
	
	return num
}
```

* 함수를 호출하면서 error를 다루는 예

```swift
do {
	let price = try parsingInteger(numString: "$100")
} catch IntParsingError.invalidInput(let invalid) {
	print("Invalid String: \(invalid)")
} catch IntParsingError.overflow {
	print("Overflow error")
} catch {
	print("Other error")
}
```


























